import { describe, it, expect, beforeEach, vi } from 'vitest'

/**
 * @test Error Handler Integration Tests
 * @description Tests for error handling, classification, logging, and retry mechanisms
 * @coverage Error classification, user-friendly messages, retry logic, error logging
 */

// Mock error types
class ValidationError extends Error {
  constructor(message: string) {
    super(message)
    this.name = 'ValidationError'
  }
}

class NetworkError extends Error {
  constructor(message: string) {
    super(message)
    this.name = 'NetworkError'
  }
}

// Mock error handler
class ErrorHandler {
  private errorLog: any[] = []
  private retryAttempts = new Map<string, number>()
  private maxRetries = 3

  classifyError(error: Error) {
    if (error instanceof ValidationError) {
      return { type: 'validation', severity: 'low', retryable: false }
    }
    if (error instanceof NetworkError) {
      return { type: 'network', severity: 'medium', retryable: true }
    }
    return { type: 'unknown', severity: 'high', retryable: false }
  }

  getUserFriendlyMessage(error: Error) {
    const classification = this.classifyError(error)

    const messages: any = {
      validation: 'Please check your input and try again.',
      network: 'Connection issue. Please try again.',
      unknown: 'An unexpected error occurred. Please contact support.'
    }

    return messages[classification.type] || messages.unknown
  }

  logError(error: Error, context?: any) {
    const classification = this.classifyError(error)

    this.errorLog.push({
      error: error.message,
      name: error.name,
      classification,
      context,
      timestamp: Date.now()
    })
  }

  async retryOperation(operation: () => Promise<any>, key: string) {
    const attempts = this.retryAttempts.get(key) || 0

    try {
      const result = await operation()
      this.retryAttempts.delete(key)
      return result
    } catch (error) {
      const classification = this.classifyError(error as Error)

      if (!classification.retryable || attempts >= this.maxRetries) {
        this.retryAttempts.delete(key)
        throw error
      }

      this.retryAttempts.set(key, attempts + 1)
      await new Promise(resolve => setTimeout(resolve, 100 * (attempts + 1)))
      return this.retryOperation(operation, key)
    }
  }

  getErrorLog() {
    return this.errorLog
  }

  getRetryCount(key: string) {
    return this.retryAttempts.get(key) || 0
  }

  clearLog() {
    this.errorLog = []
    this.retryAttempts.clear()
  }
}

describe('Error Handler Integration', () => {
  let errorHandler: ErrorHandler

  beforeEach(() => {
    errorHandler = new ErrorHandler()
  })

  // Test 1: Error Classification - Validation
  it('should classify validation errors correctly', () => {
    const error = new ValidationError('Invalid email')
    const classification = errorHandler.classifyError(error)

    expect(classification.type).toBe('validation')
    expect(classification.severity).toBe('low')
    expect(classification.retryable).toBe(false)
  })

  // Test 2: Error Classification - Network
  it('should classify network errors correctly', () => {
    const error = new NetworkError('Connection timeout')
    const classification = errorHandler.classifyError(error)

    expect(classification.type).toBe('network')
    expect(classification.severity).toBe('medium')
    expect(classification.retryable).toBe(true)
  })

  // Test 3: Error Classification - Unknown
  it('should classify unknown errors correctly', () => {
    const error = new Error('Something went wrong')
    const classification = errorHandler.classifyError(error)

    expect(classification.type).toBe('unknown')
    expect(classification.severity).toBe('high')
    expect(classification.retryable).toBe(false)
  })

  // Test 4: User-Friendly Messages - Validation
  it('should provide user-friendly message for validation errors', () => {
    const error = new ValidationError('Invalid input')
    const message = errorHandler.getUserFriendlyMessage(error)

    expect(message).toBe('Please check your input and try again.')
  })

  // Test 5: User-Friendly Messages - Network
  it('should provide user-friendly message for network errors', () => {
    const error = new NetworkError('Connection lost')
    const message = errorHandler.getUserFriendlyMessage(error)

    expect(message).toBe('Connection issue. Please try again.')
  })

  // Test 6: User-Friendly Messages - Unknown
  it('should provide user-friendly message for unknown errors', () => {
    const error = new Error('Unexpected error')
    const message = errorHandler.getUserFriendlyMessage(error)

    expect(message).toBe('An unexpected error occurred. Please contact support.')
  })

  // Test 7: Error Logging
  it('should log errors with classification', () => {
    const error = new ValidationError('Invalid data')
    errorHandler.logError(error)

    const log = errorHandler.getErrorLog()
    expect(log).toHaveLength(1)
    expect(log[0].error).toBe('Invalid data')
    expect(log[0].classification.type).toBe('validation')
  })

  // Test 8: Error Logging with Context
  it('should log errors with context', () => {
    const error = new Error('Test error')
    const context = { userId: '123', action: 'create' }

    errorHandler.logError(error, context)

    const log = errorHandler.getErrorLog()
    expect(log[0].context).toEqual(context)
  })

  // Test 9: Retry Mechanism - Success
  it('should retry and succeed on retryable operation', async () => {
    let attempts = 0
    const operation = async () => {
      attempts++
      if (attempts < 2) throw new NetworkError('Temporary failure')
      return 'success'
    }

    const result = await errorHandler.retryOperation(operation, 'test-op')

    expect(result).toBe('success')
    expect(attempts).toBe(2)
  })

  // Test 10: Retry Mechanism - Max Retries
  it('should fail after max retries', async () => {
    const operation = async () => {
      throw new NetworkError('Persistent failure')
    }

    await expect(errorHandler.retryOperation(operation, 'test-op'))
      .rejects.toThrow('Persistent failure')
  })

  // Test 11: Retry Count Tracking
  it('should track retry attempts', async () => {
    let attempts = 0
    const operation = async () => {
      attempts++
      if (attempts < 3) throw new NetworkError('Temporary failure')
      return 'success'
    }

    await errorHandler.retryOperation(operation, 'test-op')

    // After success, retry count should be cleared
    expect(errorHandler.getRetryCount('test-op')).toBe(0)
  })

  // Test 12: Non-Retryable Errors
  it('should not retry non-retryable errors', async () => {
    const operation = async () => {
      throw new ValidationError('Invalid input')
    }

    await expect(errorHandler.retryOperation(operation, 'test-op'))
      .rejects.toThrow('Invalid input')

    expect(errorHandler.getRetryCount('test-op')).toBe(0)
  })

  // Test 13: Error Log Timestamps
  it('should include timestamps in error log', () => {
    const error = new Error('Test error')
    errorHandler.logError(error)

    const log = errorHandler.getErrorLog()
    expect(log[0].timestamp).toBeDefined()
    expect(log[0].timestamp).toBeGreaterThan(0)
  })

  // Test 14: Multiple Error Logging
  it('should log multiple errors', () => {
    errorHandler.logError(new ValidationError('Error 1'))
    errorHandler.logError(new NetworkError('Error 2'))
    errorHandler.logError(new Error('Error 3'))

    const log = errorHandler.getErrorLog()
    expect(log).toHaveLength(3)
  })

  // Test 15: Clear Error Log
  it('should clear error log', () => {
    errorHandler.logError(new Error('Test error'))

    errorHandler.clearLog()

    expect(errorHandler.getErrorLog()).toHaveLength(0)
  })

  // Test 16: Error Name Recording
  it('should record error name in log', () => {
    const error = new ValidationError('Test')
    errorHandler.logError(error)

    const log = errorHandler.getErrorLog()
    expect(log[0].name).toBe('ValidationError')
  })

  // Test 17: Retry Backoff
  it('should implement exponential backoff for retries', async () => {
    const timestamps: number[] = []
    let attempts = 0

    const operation = async () => {
      timestamps.push(Date.now())
      attempts++
      if (attempts < 3) throw new NetworkError('Temporary failure')
      return 'success'
    }

    await errorHandler.retryOperation(operation, 'test-op')

    // Check that delays increase (approximately)
    expect(timestamps).toHaveLength(3)
  })

  // Test 18: Concurrent Error Handling
  it('should handle concurrent errors', () => {
    const errors = [
      new ValidationError('Error 1'),
      new NetworkError('Error 2'),
      new Error('Error 3')
    ]

    errors.forEach(err => errorHandler.logError(err))

    const log = errorHandler.getErrorLog()
    expect(log).toHaveLength(3)
  })

  // Test 19: Error Classification Consistency
  it('should consistently classify same error types', () => {
    const error1 = new ValidationError('Test 1')
    const error2 = new ValidationError('Test 2')

    const class1 = errorHandler.classifyError(error1)
    const class2 = errorHandler.classifyError(error2)

    expect(class1.type).toBe(class2.type)
    expect(class1.severity).toBe(class2.severity)
  })

  // Test 20: Error Log Structure
  it('should maintain consistent error log structure', () => {
    const error = new NetworkError('Test error')
    const context = { test: true }

    errorHandler.logError(error, context)

    const log = errorHandler.getErrorLog()[0]

    expect(log).toHaveProperty('error')
    expect(log).toHaveProperty('name')
    expect(log).toHaveProperty('classification')
    expect(log).toHaveProperty('context')
    expect(log).toHaveProperty('timestamp')
  })
})
